<?xml version="1.0" encoding="utf-8"?>
<!-- This URDF was automatically created by SolidWorks to URDF Exporter! Originally created by Stephen Brawner (brawner@gmail.com) 
     Commit Version: 1.5.1-0-g916b5db  Build Version: 1.5.7152.31018
     For more information, please see http://wiki.ros.org/sw_urdf_exporter -->
<robot
  name="IRB13009">
<link
    name="world"/>
<joint name="fixed" type="fixed">
<parent link="world"/>
<child link="base_link"/>
</joint>
  <link
    name="base_link">
    <inertial>
      <origin
        xyz="-0.022011 -0.00063814 0.12757"
        rpy="0 0 0" />
      <mass
        value="13.179" />
      <inertia
        ixx="0.11221"
        ixy="-0.00070945"
        ixz="-0.0034124"
        iyy="0.14132"
        iyz="0.00011866"
        izz="0.11734" />
    </inertial>
    <visual>
      <origin
        xyz="0 0 0"
        rpy="0 0 0" />
      <geometry>
        <mesh
          filename="package://IRB13009/meshes/base_link.STL" />
      </geometry>
      <material
        name="">
        <color
          rgba="0.79216 0.81961 0.93333 1" />
      </material>
    </visual>
    <collision>
      <origin
        xyz="0 0 0"
        rpy="0 0 0" />
      <geometry>
        <mesh
          filename="package://IRB13009/meshes/base_link.STL" />
      </geometry>
    </collision>
  </link>
  <link
    name="Link1">
    <inertial>
      <origin
        xyz="0.039272 0.0012718 0.14588"
        rpy="0 0 0" />
      <mass
        value="16.333" />
      <inertia
        ixx="0.33225"
        ixy="-0.0018868"
        ixz="-0.073712"
        iyy="0.25386"
        iyz="-0.0019972"
        izz="0.29757" />
    </inertial>
    <visual>
      <origin
        xyz="0 0 0"
        rpy="0 0 0" />
      <geometry>
        <mesh
          filename="package://IRB13009/meshes/Link1.STL" />
      </geometry>
      <material
        name="">
        <color
          rgba="0.79216 0.81961 0.93333 1" />
      </material>
    </visual>
    <collision>
      <origin
        xyz="0 0 0"
        rpy="0 0 0" />
      <geometry>
        <mesh
          filename="package://IRB13009/meshes/Link1.STL" />
      </geometry>
    </collision>
  </link>
  <joint
    name="joint1"
    type="revolute">
    <origin
      xyz="-0.001358 -0.0020449 0.254"
      rpy="0 0 0" />
    <parent
      link="base_link" />
    <child
      link="Link1" />
    <axis
      xyz="0 0 1" />
    <limit
      lower="-3.14"
      upper="3.14"
      effort="0"
      velocity="3.14" />
  </joint>
  <link
    name="Link2">
    <inertial>
      <origin
        xyz="-0.010943 -0.24496 0.0021765"
        rpy="0 0 0" />
      <mass
        value="15.441" />
      <inertia
        ixx="0.74674"
        ixy="-0.0028972"
        ixz="7.1024E-05"
        iyy="0.10329"
        iyz="0.0060074"
        izz="0.69286" />
    </inertial>
    <visual>
      <origin
        xyz="0 0 0"
        rpy="0 0 0" />
      <geometry>
        <mesh
          filename="package://IRB13009/meshes/Link2.STL" />
      </geometry>
      <material
        name="">
        <color
          rgba="0.79216 0.81961 0.93333 1" />
      </material>
    </visual>
    <collision>
      <origin
        xyz="0 0 0"
        rpy="0 0 0" />
      <geometry>
        <mesh
          filename="package://IRB13009/meshes/Link2.STL" />
      </geometry>
    </collision>
  </link>
  <joint
    name="joint2"
    type="revolute">
    <origin
      xyz="0.15136 -0.00095513 0.29"
      rpy="-1.5708 0 0" />
    <parent
      link="Link1" />
    <child
      link="Link2" />
    <axis
      xyz="0 0 1" />
    <limit
      lower="-1.66"
      upper="2.7"
      effort="0"
      velocity="3.14" />
  </joint>
  <link
    name="Link3">
    <inertial>
      <origin
        xyz="0.0058315 -0.011409 0.0021795"
        rpy="0 0 0" />
      <mass
        value="4.4174" />
      <inertia
        ixx="0.014813"
        ixy="0.0015497"
        ixz="4.1831E-06"
        iyy="0.022565"
        iyz="0.00010668"
        izz="0.025905" />
    </inertial>
    <visual>
      <origin
        xyz="0 0 0"
        rpy="0 0 0" />
      <geometry>
        <mesh
          filename="package://IRB13009/meshes/Link3.STL" />
      </geometry>
      <material
        name="">
        <color
          rgba="0.79216 0.81961 0.93333 1" />
      </material>
    </visual>
    <collision>
      <origin
        xyz="0 0 0"
        rpy="0 0 0" />
      <geometry>
        <mesh
          filename="package://IRB13009/meshes/Link3.STL" />
      </geometry>
    </collision>
  </link>
  <joint
    name="joint3"
    type="revolute">
    <origin
      xyz="0 -0.575 -0.000500000000001014"
      rpy="0 0 0" />
    <parent
      link="Link2" />
    <child
      link="Link3" />
    <axis
      xyz="0 0 1" />
    <limit
      lower="-3.576"
      upper="1.13"
      effort="0"
      velocity="3.14" />
  </joint>
  <link
    name="Link4">
    <inertial>
      <origin
        xyz="-0.0012965 -0.0013344 0.13876"
        rpy="0 0 0" />
      <mass
        value="3.6943" />
      <inertia
        ixx="0.032938"
        ixy="7.4225E-07"
        ixz="-0.00024846"
        iyy="0.031458"
        iyz="0.00090596"
        izz="0.0089953" />
    </inertial>
    <visual>
      <origin
        xyz="0 0 0"
        rpy="0 0 0" />
      <geometry>
        <mesh
          filename="package://IRB13009/meshes/Link4.STL" />
      </geometry>
      <material
        name="">
        <color
          rgba="0.79216 0.81961 0.93333 1" />
      </material>
    </visual>
    <collision>
      <origin
        xyz="0 0 0"
        rpy="0 0 0" />
      <geometry>
        <mesh
          filename="package://IRB13009/meshes/Link4.STL" />
      </geometry>
    </collision>
  </link>
  <joint
    name="joint4"
    type="revolute">
    <origin
      xyz="0.129499999999999 -0.0400000000000018 0.00346878624711097"
      rpy="1.5707963267949 0 1.57079632679488" />
    <parent
      link="Link3" />
    <child
      link="Link4" />
    <axis
      xyz="0 0 1" />
    <limit
      lower="-4.01"
      upper="4.01"
      effort="0"
      velocity="3.14" />
  </joint>
  <link
    name="Link5">
    <inertial>
      <origin
        xyz="0.020485 -5.7665E-05 -0.0030232"
        rpy="0 0 0" />
      <mass
        value="0.58519" />
      <inertia
        ixx="0.00050022"
        ixy="-2.2152E-06"
        ixz="0.00010018"
        iyy="0.00096426"
        iyz="-6.585E-08"
        izz="0.0010149" />
    </inertial>
    <visual>
      <origin
        xyz="0 0 0"
        rpy="0 0 0" />
      <geometry>
        <mesh
          filename="package://IRB13009/meshes/Link5.STL" />
      </geometry>
      <material
        name="">
        <color
          rgba="0.79216 0.81961 0.93333 1" />
      </material>
    </visual>
    <collision>
      <origin
        xyz="0 0 0"
        rpy="0 0 0" />
      <geometry>
        <mesh
          filename="package://IRB13009/meshes/Link5.STL" />
      </geometry>
    </collision>
  </link>
  <joint
    name="joint5"
    type="revolute">
    <origin
      xyz="0 0.0119312137528833 0.295500659405754"
      rpy="1.5707963267949 -1.5707963267949 0" />
    <parent
      link="Link4" />
    <child
      link="Link5" />
    <axis
      xyz="0 0 -1" />
    <limit
      lower="-2.67"
      upper="2.67"
      effort="0"
      velocity="3.14" />
  </joint>
  <link
    name="Link6">
    <inertial>
      <origin
        xyz="1.5146E-05 -2.7743E-05 -0.0030398"
        rpy="0 0 0" />
      <mass
        value="0.0079003" />
      <inertia
        ixx="1.5145E-06"
        ixy="1.1695E-08"
        ixz="2.425E-11"
        iyy="1.5997E-06"
        iyz="-4.4418E-11"
        izz="3.0678E-06" />
    </inertial>
    <visual>
      <origin
        xyz="0 0 0"
        rpy="0 0 0" />
      <geometry>
        <mesh
          filename="package://IRB13009/meshes/Link6.STL" />
      </geometry>
      <material
        name="">
        <color
          rgba="0.79216 0.81961 0.93333 1" />
      </material>
    </visual>
    <collision>
      <origin
        xyz="0 0 0"
        rpy="0 0 0" />
      <geometry>
        <mesh
          filename="package://IRB13009/meshes/Link6.STL" />
      </geometry>
    </collision>
  </link>
  <joint
    name="joint6"
    type="revolute">
    <origin
      xyz="0.0899993405942459 -9.18323552119293E-05 -0.0117308690068843"
      rpy="1.5707963267949 0 1.5707963267949" />
    <parent
      link="Link5" />
    <child
      link="Link6" />
    <axis
      xyz="0 0 1" />
    <limit
      lower="-6.98"
      upper="6.98"
      effort="0"
      velocity="3.14" />
  </joint>

<!-- Gazebo-specific link properties -->
    <gazebo reference="base_link">
      <turnGravityOff>true</turnGravityOff>
    </gazebo>
    <gazebo reference="Link1">
      <turnGravityOff>true</turnGravityOff>
    </gazebo>
    <gazebo reference="Link2">
      <turnGravityOff>true</turnGravityOff>
    </gazebo>
    <gazebo reference="Link3">
      <turnGravityOff>true</turnGravityOff>
    </gazebo>
    <gazebo reference="Link4">
      <turnGravityOff>true</turnGravityOff>
    </gazebo>
    <gazebo reference="Link5">
      <turnGravityOff>true</turnGravityOff>
    </gazebo>
    <gazebo reference="Link6">
      <turnGravityOff>true</turnGravityOff>
    </gazebo>

</robot>
